Workbook

Sheet Фин рез
A1: Мос биржа | D1: Exante
A2: 44258 | B2: ='03.03.21'!F139 -> -654.854
A3: 44259 | B3: ='04.03.21'!F45 -> 35.99
A4: 44260 | B4: ='05.03.21'!F38 -> -20343.043
A5: 44264 | B5: ='09.03.21'!F23 -> -0.017
A6: 44265 | B6: 0
A7: 44266 | B7: ='11.03.21'!F10 -> -6713.17
A8: 44267 | B8: ='12.03.21'!F25 -> 171645.51
A9: 44270 | B9: ='15.03.21'!F11 -> -30.404444
A10: 44271 | B10: ='16.03.21'!N75 -> 249.464
A11: 44272 | B11: ='17.03.21'!M91 -> 193783.28
A12: 44273 | B12: ='18.03.21'!N10 -> 28.77
A13: 44274 | B13: ='19.03.21'!H72 -> -18741.954
B14: =SUM(B2:B13) -> 319259.57 | D14: =Exante!L45 -> 0.648

Sheet Exante
A1: Пользователь | B1: счет | C1: дата | D1: id | E1: валюта | F1: направление | G1: количесво | H1: цена | I1: комиссия | J1: номер | K1: p&l | L1: фин рез
A2: traderbotFT8@yandex.ru | B2: VPX8288.032 | C2: 44274.318 | D2: B.ICE.M2021 | E2: USD | F2: Sell | G2: 1 | H2: 63.27 | I2: 1.67 | J2: 70d61a28-3529-4a36-9466-663625b48861 | K2: 0 | L2: =IF(F2="Sell",H2*G2,-H2*G2) -> 63.27
A3: traderbotFT8@yandex.ru | B3: VPX8288.032 | C3: 44274.318 | D3: B.ICE.M2021 | E3: USD | F3: Sell | G3: 1 | H3: 63.27 | I3: 1.67 | J3: 9aa193a4-9898-4ef2-872e-50ad97168784 | K3: 0 | L3: =IF(F3="Sell",H3*G3,-H3*G3) -> 63.27
A4: traderbotFT8@yandex.ru | B4: VPX8288.032 | C4: 44274.318 | D4: B.ICE.M2021 | E4: USD | F4: Sell | G4: 1 | H4: 63.27 | I4: 1.67 | J4: a1d8ecb6-c339-421a-ba2b-53419e6eb2fb | K4: -1484 | L4: =IF(F4="Sell",H4*G4,-H4*G4) -> 63.27
A5: traderbotFT8@yandex.ru | B5: VPX8288.032 | C5: 44274.318 | D5: B.ICE.M2021 | E5: USD | F5: Sell | G5: 1 | H5: 63.27 | I5: 1.67 | J5: 02e00cde-18d1-44ae-8b9a-71b1db3413da | K5: -1484 | L5: =IF(F5="Sell",H5*G5,-H5*G5) -> 63.27
A6: traderbotFT8@yandex.ru | B6: VPX8288.032 | C6: 44274.318 | D6: B.ICE.M2021 | E6: USD | F6: Sell | G6: 1 | H6: 63.27 | I6: 1.67 | J6: b9208da8-6912-42f6-a417-53b820eab65b | K6: -1484 | L6: =IF(F6="Sell",H6*G6,-H6*G6) -> 63.27
A7: traderbotFT8@yandex.ru | B7: VPX8288.032 | C7: 44274.318 | D7: B.ICE.M2021 | E7: USD | F7: Sell | G7: 1 | H7: 63.28 | I7: 1.67 | J7: 46af0540-5713-4b8a-9c1b-21bfbb107210 | K7: -1474 | L7: =IF(F7="Sell",H7*G7,-H7*G7) -> 63.28
A8: traderbotFT8@yandex.ru | B8: VPX8288.032 | C8: 44274.318 | D8: B.ICE.M2021 | E8: USD | F8: Sell | G8: 1 | H8: 63.28 | I8: 1.67 | J8: 1625d27a-5eaa-426f-a1d0-f85cf773d9f3 | K8: -1474 | L8: =IF(F8="Sell",H8*G8,-H8*G8) -> 63.28
A9: traderbotFT8@yandex.ru | B9: VPX8288.032 | C9: 44274.318 | D9: B.ICE.M2021 | E9: USD | F9: Buy | G9: 1 | H9: 63.29 | I9: 1.67 | J9: 96520ccf-e871-4f9a-bf0f-f40e81845a02 | K9: 0 | L9: =IF(F9="Sell",H9*G9,-H9*G9) -> -63.29
A10: traderbotFT8@yandex.ru | B10: VPX8288.032 | C10: 44274.318 | D10: B.ICE.M2021 | E10: USD | F10: Buy | G10: 1 | H10: 63.29 | I10: 1.67 | J10: 96520ccf-e871-4f9a-bf0f-f40e81845a02 | K10: 0 | L10: =IF(F10="Sell",H10*G10,-H10*G10) -> -63.29
A11: traderbotFT8@yandex.ru | B11: VPX8288.032 | C11: 44274.318 | D11: B.ICE.M2021 | E11: USD | F11: Sell | G11: 1 | H11: 63.25 | I11: 1.67 | J11: d95718f3-3d7f-4dce-b52a-698f8e985992 | K11: -2480 | L11: =IF(F11="Sell",H11*G11,-H11*G11) -> 63.25
A12: traderbotFT8@yandex.ru | B12: VPX8288.032 | C12: 44274.318 | D12: B.ICE.K2021 | E12: USD | F12: Buy | G12: 1 | H12: 63.45 | I12: 1.67 | J12: 6ef195fe-d519-4176-aa9c-c5254f883ca0 | K12: 0 | L12: =IF(F12="Sell",H12*G12,-H12*G12) -> -63.45
A13: traderbotFT8@yandex.ru | B13: VPX8288.032 | C13: 44274.318 | D13: B.ICE.M2021 | E13: USD | F13: Buy | G13: 1 | H13: 63.25 | I13: 1.67 | J13: 3a501016-741e-4b15-b1c0-6a2903d4a0e4 | K13: 0 | L13: =IF(F13="Sell",H13*G13,-H13*G13) -> -63.25
... A44: traderbotFT8@yandex.ru | B44: VPX8288.032 | C44: 44258.292 | D44: GC.COMEX.J2021 | E44: USD | F44: Sell | G44: 2 | H44: 1733.1 | I44: 4.8 | J44: 0589d008-e6ae-4359-92cc-ff9810df9012 | K44: 0 | L44: =IF(F44="Sell",H44*G44,-H44*G44) -> 3466.2
L45: =SUM(L2:L44) -> 0.648

Sheet 03.03.21
A1: Время | B1: Инструмент | C1: Операция | D1: Цена | E1: Кол-во | F1: Фин рез
A2: 0.42221065 | B2: GDH1 [МБ Деривативы: Фьючерсы] | C2: Продажа | D2: 1732 | E2: 76 | F2: =IF(C2="Продажа",D2*E2,-D2*E2) -> 131632
A3: 0.42099537 | B3: GDH1 [МБ Деривативы: Фьючерсы] | C3: Продажа | D3: 1732 | E3: 9 | F3: =IF(C3="Продажа",D3*E3,-D3*E3) -> 15588
A4: 0.42099537 | B4: GDH1 [МБ Деривативы: Фьючерсы] | C4: Продажа | D4: 1732 | E4: 1 | F4: =IF(C4="Продажа",D4*E4,-D4*E4) -> 1732
A5: 0.42099537 | B5: GDH1 [МБ Деривативы: Фьючерсы] | C5: Продажа | D5: 1732 | E5: 10 | F5: =IF(C5="Продажа",D5*E5,-D5*E5) -> 17320
A6: 0.42099537 | B6: GDH1 [МБ Деривативы: Фьючерсы] | C6: Продажа | D6: 1732 | E6: 1 | F6: =IF(C6="Продажа",D6*E6,-D6*E6) -> 1732
A7: 0.42099537 | B7: GDH1 [МБ Деривативы: Фьючерсы] | C7: Продажа | D7: 1732 | E7: 2 | F7: =IF(C7="Продажа",D7*E7,-D7*E7) -> 3464
A8: 0.42099537 | B8: GDH1 [МБ Деривативы: Фьючерсы] | C8: Продажа | D8: 1732 | E8: 1 | F8: =IF(C8="Продажа",D8*E8,-D8*E8) -> 1732
A9: 0.42099537 | B9: GDH1 [МБ Деривативы: Фьючерсы] | C9: Продажа | D9: 1732 | E9: 10 | F9: =IF(C9="Продажа",D9*E9,-D9*E9) -> 17320
A10: 0.42099537 | B10: GDH1 [МБ Деривативы: Фьючерсы] | C10: Продажа | D10: 1732.1 | E10: 10 | F10: =IF(C10="Продажа",D10*E10,-D10*E10) -> 17321
A11: 0.42099537 | B11: GDH1 [МБ Деривативы: Фьючерсы] | C11: Продажа | D11: 1732.1 | E11: 3 | F11: =IF(C11="Продажа",D11*E11,-D11*E11) -> 5196.3
A12: 0.42099537 | B12: GDH1 [МБ Деривативы: Фьючерсы] | C12: Продажа | D12: 1732.1 | E12: 3 | F12: =IF(C12="Продажа",D12*E12,-D12*E12) -> 5196.3
A13: 0.42087963 | B13: GDH1 [МБ Деривативы: Фьючерсы] | C13: Продажа | D13: 1731.9 | E13: 3 | F13: =IF(C13="Продажа",D13*E13,-D13*E13) -> 5195.7
... A138: 0.29196759 | B138: BRJ1 [МБ Деривативы: Фьючерсы] | C138: Купля | D138: 62.97 | E138: 20 | F138: =IF(C138="Продажа",D138*E138,-D138*E138) -> -1259.4
F139: =SUM(F2:F138) -> -654.854

Sheet 04.03.21
A1: Время | B1: Инструмент | C1: Операция | D1: Цена | E1: Кол-во | F1: Фин рез
A2: 0.40931713 | B2: BRK1 [МБ Деривативы: Фьючерсы] | C2: Продажа | D2: 63.9 | E2: 1 | F2: =IF(C2="Продажа",D2*E2,-D2*E2) -> 63.9
A3: 0.40931713 | B3: BRK1 [МБ Деривативы: Фьючерсы] | C3: Продажа | D3: 63.9 | E3: 1 | F3: =IF(C3="Продажа",D3*E3,-D3*E3) -> 63.9
A4: 0.40931713 | B4: BRK1 [МБ Деривативы: Фьючерсы] | C4: Продажа | D4: 63.9 | E4: 1 | F4: =IF(C4="Продажа",D4*E4,-D4*E4) -> 63.9
A5: 0.40931713 | B5: BRK1 [МБ Деривативы: Фьючерсы] | C5: Продажа | D5: 63.9 | E5: 1 | F5: =IF(C5="Продажа",D5*E5,-D5*E5) -> 63.9
A6: 0.40931713 | B6: BRK1 [МБ Деривативы: Фьючерсы] | C6: Продажа | D6: 63.9 | E6: 1 | F6: =IF(C6="Продажа",D6*E6,-D6*E6) -> 63.9
A7: 0.40931713 | B7: BRK1 [МБ Деривативы: Фьючерсы] | C7: Продажа | D7: 63.9 | E7: 6 | F7: =IF(C7="Продажа",D7*E7,-D7*E7) -> 383.4
A8: 0.40931713 | B8: BRK1 [МБ Деривативы: Фьючерсы] | C8: Продажа | D8: 63.9 | E8: 3 | F8: =IF(C8="Продажа",D8*E8,-D8*E8) -> 191.7
A9: 0.40788194 | B9: BRK1 [МБ Деривативы: Фьючерсы] | C9: Продажа | D9: 63.9 | E9: 1 | F9: =IF(C9="Продажа",D9*E9,-D9*E9) -> 63.9
A10: 0.40115741 | B10: BRK1 [МБ Деривативы: Фьючерсы] | C10: Купля | D10: 63.79 | E10: 15 | F10: =IF(C10="Продажа",D10*E10,-D10*E10) -> -956.85
A11: 0.39413194 | B11: BRK1 [МБ Деривативы: Фьючерсы] | C11: Продажа | D11: 64.04 | E11: 12 | F11: =IF(C11="Продажа",D11*E11,-D11*E11) -> 768.48
A12: 0.3941088 | B12: BRK1 [МБ Деривативы: Фьючерсы] | C12: Продажа | D12: 64.04 | E12: 2 | F12: =IF(C12="Продажа",D12*E12,-D12*E12) -> 128.08
A13: 0.3940162 | B13: BRK1 [МБ Деривативы: Фьючерсы] | C13: Продажа | D13: 64.04 | E13: 2 | F13: =IF(C13="Продажа",D13*E13,-D13*E13) -> 128.08
... A44: 0.29545139 | B44: SVH1 [МБ Деривативы: Фьючерсы] | C44: Купля | D44: 25.95 | E44: 1000 | F44: =IF(C44="Продажа",D44*E44,-D44*E44) -> -25950
F45: =SUM(F2:F44) -> 35.99

Sheet 05.03.21
A1: Время | B1: Инструмент | C1: Операция | D1: Цена | E1: Кол-во | F1: Фин рез
A2: 0.40114583 | B2: GDH1 [МБ Деривативы: Фьючерсы] | C2: Купля | D2: 1696.7 | E2: 1 | F2: =IF(C2="Продажа",D2*E2,-D2*E2) -> -1696.7
A3: 0.40114583 | B3: GDH1 [МБ Деривативы: Фьючерсы] | C3: Купля | D3: 1696.7 | E3: 8 | F3: =IF(C3="Продажа",D3*E3,-D3*E3) -> -13573.6
A4: 0.40114583 | B4: GDH1 [МБ Деривативы: Фьючерсы] | C4: Купля | D4: 1696.7 | E4: 3 | F4: =IF(C4="Продажа",D4*E4,-D4*E4) -> -5090.1
A5: 0.37113426 | B5: NGH1 [МБ Деривативы: Фьючерсы] | C5: Продажа | D5: 2.719 | E5: 1 | F5: =IF(C5="Продажа",D5*E5,-D5*E5) -> 2.719
A6: 0.37040509 | B6: NGH1 [МБ Деривативы: Фьючерсы] | C6: Продажа | D6: 2.719 | E6: 2 | F6: =IF(C6="Продажа",D6*E6,-D6*E6) -> 5.438
A7: 0.36283565 | B7: BRK1 [МБ Деривативы: Фьючерсы] | C7: Продажа | D7: 66.79 | E7: 1 | F7: =IF(C7="Продажа",D7*E7,-D7*E7) -> 66.79
A8: 0.33888889 | B8: NGH1 [МБ Деривативы: Фьючерсы] | C8: Купля | D8: 2.717 | E8: 3 | F8: =IF(C8="Продажа",D8*E8,-D8*E8) -> -8.151
A9: 0.33131944 | B9: NGH1 [МБ Деривативы: Фьючерсы] | C9: Продажа | D9: 2.72 | E9: 1 | F9: =IF(C9="Продажа",D9*E9,-D9*E9) -> 2.72
A10: 0.32811343 | B10: NGH1 [МБ Деривативы: Фьючерсы] | C10: Купля | D10: 2.719 | E10: 1 | F10: =IF(C10="Продажа",D10*E10,-D10*E10) -> -2.719
A11: 0.32799769 | B11: BRK1 [МБ Деривативы: Фьючерсы] | C11: Купля | D11: 66.74 | E11: 1 | F11: =IF(C11="Продажа",D11*E11,-D11*E11) -> -66.74
A12: 0.31962963 | B12: GDH1 [МБ Деривативы: Фьючерсы] | C12: Купля | D12: 1695.7 | E12: 3 | F12: =IF(C12="Продажа",D12*E12,-D12*E12) -> -5087.1
A13: 0.31903935 | B13: GDH1 [МБ Деривативы: Фьючерсы] | C13: Купля | D13: 1695.8 | E13: 3 | F13: =IF(C13="Продажа",D13*E13,-D13*E13) -> -5087.4
... A37: 0.29614583 | B37: BRK1 [МБ Деривативы: Фьючерсы] | C37: Продажа | D37: 66.72 | E37: 10 | F37: =IF(C37="Продажа",D37*E37,-D37*E37) -> 667.2
F38: =SUM(F2:F37) -> -20343.043

Sheet 09.03.21
A1: Время | B1: Код инструмента | C1: Операция | D1: Цена | E1: Кол-во | F1: Фин рез
A2: 0.40813657 | B2: NGH1 | C2: Продажа | D2: 2.647 | E2: 4 | F2: =IF(C2="Продажа",D2*E2,-D2*E2) -> 10.588
A3: 0.40541667 | B3: NGH1 | C3: Продажа | D3: 2.655 | E3: 1 | F3: =IF(C3="Продажа",D3*E3,-D3*E3) -> 2.655
A4: 0.40357639 | B4: NGH1 | C4: Продажа | D4: 2.648 | E4: 2 | F4: =IF(C4="Продажа",D4*E4,-D4*E4) -> 5.296
A5: 0.40357639 | B5: NGH1 | C5: Продажа | D5: 2.648 | E5: 2 | F5: =IF(C5="Продажа",D5*E5,-D5*E5) -> 5.296
A6: 0.39869213 | B6: NGH1 | C6: Продажа | D6: 2.656 | E6: 24 | F6: =IF(C6="Продажа",D6*E6,-D6*E6) -> 63.744
A7: 0.38912037 | B7: NGH1 | C7: Купля | D7: 2.663 | E7: 2 | F7: =IF(C7="Продажа",D7*E7,-D7*E7) -> -5.326
A8: 0.38857639 | B8: NGH1 | C8: Купля | D8: 2.668 | E8: 13 | F8: =IF(C8="Продажа",D8*E8,-D8*E8) -> -34.684
A9: 0.38842593 | B9: NGH1 | C9: Купля | D9: 2.668 | E9: 33 | F9: =IF(C9="Продажа",D9*E9,-D9*E9) -> -88.044
A10: 0.38834491 | B10: NGH1 | C10: Купля | D10: 2.67 | E10: 12 | F10: =IF(C10="Продажа",D10*E10,-D10*E10) -> -32.04
A11: 0.38834491 | B11: NGH1 | C11: Купля | D11: 2.67 | E11: 1 | F11: =IF(C11="Продажа",D11*E11,-D11*E11) -> -2.67
A12: 0.38834491 | B12: NGH1 | C12: Купля | D12: 2.67 | E12: 1 | F12: =IF(C12="Продажа",D12*E12,-D12*E12) -> -2.67
A13: 0.38834491 | B13: NGH1 | C13: Купля | D13: 2.67 | E13: 1 | F13: =IF(C13="Продажа",D13*E13,-D13*E13) -> -2.67
... A22: 0.3730787 | B22: NGH1 | C22: Купля | D22: 2.65 | E22: 1 | F22: =IF(C22="Продажа",D22*E22,-D22*E22) -> -2.65
F23: =SUM(F2:F22) -> -0.017

Sheet 10.03.21
A1: (сделок не было) | B1: Время | C1: Код инструмента | D1: Операция | E1: Цена | F1: Кол-во | G1: Счет | H1: Фин рез

Sheet 11.03.21
A1: Время | B1: Код инструмента | C1: Операция | D1: Цена | E1: Кол-во | F1: Фин рез
A2: 0.36237269 | B2: BRK1 | C2: Продажа | D2: 67.83 | E2: 63 | F2: =IF(C2="Продажа",D2*E2,-D2*E2) -> 4273.29
A3: 0.36041667 | B3: BRK1 | C3: Купля | D3: 67.82 | E3: 163 | F3: =IF(C3="Продажа",D3*E3,-D3*E3) -> -11054.66
A4: 0.31060185 | B4: GDH1 | C4: Продажа | D4: 1730.4 | E4: 19 | F4: =IF(C4="Продажа",D4*E4,-D4*E4) -> 32877.6
A5: 0.30989583 | B5: GDH1 | C5: Продажа | D5: 1730.2 | E5: 1 | F5: =IF(C5="Продажа",D5*E5,-D5*E5) -> 1730.2
A6: 0.30989583 | B6: GDH1 | C6: Продажа | D6: 1730.2 | E6: 17 | F6: =IF(C6="Продажа",D6*E6,-D6*E6) -> 29413.4
A7: 0.30989583 | B7: GDH1 | C7: Продажа | D7: 1730.2 | E7: 3 | F7: =IF(C7="Продажа",D7*E7,-D7*E7) -> 5190.6
A8: 0.30989583 | B8: GDH1 | C8: Продажа | D8: 1730.2 | E8: 6 | F8: =IF(C8="Продажа",D8*E8,-D8*E8) -> 10381.2
A9: 0.30836806 | B9: GDH1 | C9: Купля | D9: 1728.8 | E9: 46 | F9: =IF(C9="Продажа",D9*E9,-D9*E9) -> -79524.8
F10: =SUM(F2:F9) -> -6713.17

Sheet 12.03.21
A1: Время | B1: Код инструмента | C1: Операция | D1: Цена | E1: Кол-во | F1: Фин рез
A2: 0.39395833 | B2: NGH1 | C2: Купля | D2: 2.691 | E2: 4 | F2: =IF(C2="Продажа",D2*E2,-D2*E2) -> -10.764
A3: 0.38912037 | B3: NGH1 | C3: Купля | D3: 2.686 | E3: 2 | F3: =IF(C3="Продажа",D3*E3,-D3*E3) -> -5.372
A4: 0.38783565 | B4: NGH1 | C4: Купля | D4: 2.685 | E4: 1 | F4: =IF(C4="Продажа",D4*E4,-D4*E4) -> -2.685
A5: 0.38783565 | B5: NGH1 | C5: Купля | D5: 2.685 | E5: 2 | F5: =IF(C5="Продажа",D5*E5,-D5*E5) -> -5.37
A6: 0.38641204 | B6: NGH1 | C6: Купля | D6: 2.682 | E6: 2 | F6: =IF(C6="Продажа",D6*E6,-D6*E6) -> -5.364
A7: 0.38445602 | B7: NGH1 | C7: Купля | D7: 2.686 | E7: 5 | F7: =IF(C7="Продажа",D7*E7,-D7*E7) -> -13.43
A8: 0.3824537 | B8: NGH1 | C8: Продажа | D8: 2.686 | E8: 16 | F8: =IF(C8="Продажа",D8*E8,-D8*E8) -> 42.976
A9: 0.38157407 | B9: NGH1 | C9: Продажа | D9: 2.683 | E9: 1 | F9: =IF(C9="Продажа",D9*E9,-D9*E9) -> 2.683
A10: 0.35106481 | B10: NGH1 | C10: Купля | D10: 2.687 | E10: 1 | F10: =IF(C10="Продажа",D10*E10,-D10*E10) -> -2.687
A11: 0.35091435 | B11: NGH1 | C11: Купля | D11: 2.688 | E11: 1 | F11: =IF(C11="Продажа",D11*E11,-D11*E11) -> -2.688
A12: 0.35084491 | B12: NGH1 | C12: Купля | D12: 2.688 | E12: 1 | F12: =IF(C12="Продажа",D12*E12,-D12*E12) -> -2.688
A13: 0.35072917 | B13: NGH1 | C13: Купля | D13: 2.689 | E13: 2 | F13: =IF(C13="Продажа",D13*E13,-D13*E13) -> -5.378
... A24: 0.29229167 | B24: GDH1 | C24: Продажа | D24: 1717.5 | E24: 174 | F24: =IF(C24="Продажа",D24*E24,-D24*E24) -> 298845
F25: =SUM(F2:F24) -> 171645.51

Sheet 15.03.21
A1: Время | B1: Код инструмента | C1: Операция | D1: Цена | E1: Кол-во | F1: Фин рез
A2: 0.35569444 | B2: GDH1 | C2: Продажа | D2: 1722.4 | E2: 12 | F2: =IF(C2="Продажа",D2*E2,-D2*E2) -> 20668.8
A3: 0.35568287 | B3: GDH1 | C3: Продажа | D3: 1722.4 | E3: 1 | F3: =IF(C3="Продажа",D3*E3,-D3*E3) -> 1722.4
A4: 0.3534838 | B4: GDH1 | C4: Купля | D4: 1723.8 | E4: 13 | F4: =IF(C4="Продажа",D4*E4,-D4*E4) -> -22409.4
A5: 0.33587963 | B5: NGH1 | C5: Купля | D5: 2.563 | E5: 100 | F5: =IF(C5="Продажа",D5*E5,-D5*E5) -> -256.3
A6: 0.33111111 | B6: BRJ1 | C6: Продажа | D6: 69.68 | E6: 36 | F6: =IF(C6="Продажа",D6*E6,-D6*E6) -> 2508.48
A7: 0.33111111 | B7: BRJ1 | C7: Продажа | D7: 69.68 | E7: 19 | F7: =IF(C7="Продажа",D7*E7,-D7*E7) -> 1323.92
A8: 0.33111111 | B8: BRJ1 | C8: Продажа | D8: 69.68 | E8: 11 | F8: =IF(C8="Продажа",D8*E8,-D8*E8) -> 766.48
A9: 0.33111111 | B9: BRJ1 | C9: Продажа | D9: 69.69 | E9: 10 | F9: =IF(C9="Продажа",D9*E9,-D9*E9) -> 696.9
A10: 0.33046296 | B10: BRJ1 | C10: Купля | D10: 69.67 | E10: 76 | F10: =IF(C10="Продажа",D10*E10,-D10*E10) -> -5294.92
F11: =AVERAGE(F2:F10) -> -30.404444

Sheet 16.03.21
A1: Время | B1: Инструмент сокр. | C1: Операция | D1: Цена | E1: Кол-во | F1: Фин рез | I1: Время | J1: Инструмент сокр. | K1: Операция | L1: Цена | M1: Кол-во | N1: Фин рез | U1: Время | V1: Инструмент сокр. | W1: Операция | X1: Цена | Y1: Кол-во | Z1: Счет | AA1: Фин рез
A2: 0.4021875 | B2: NGH1 | C2: Купля | D2: 2.513 | E2: 5 | F2: =IF(C2="Продажа",D2*E2,-D2*E2) -> -12.565 | I2: 0.4021875 | J2: NGH1 | K2: Купля | L2: 2.513 | M2: 5 | N2: =IF(K2="Продажа",M2*L2,-M2*L2) -> -12.565 | T2: 1 | U2: 0.85674769 | V2: SiM1 | W2: Купля | X2: 73616 | Y2: 3 | Z2: U7A0067 | AA2: =IF(W2="Продажа",X2*Y2,-X2*Y2) -> -220848
A3: 0.4021875 | B3: NGH1 | C3: Купля | D3: 2.51 | E3: 2 | F3: =IF(C3="Продажа",D3*E3,-D3*E3) -> -5.02 | I3: 0.4021875 | J3: NGH1 | K3: Купля | L3: 2.51 | M3: 2 | N3: =IF(K3="Продажа",M3*L3,-M3*L3) -> -5.02 | T3: 2 | U3: 0.85674769 | V3: SiH1 | W3: Продажа | X3: 72838 | Y3: 3 | Z3: U7A0067 | AA3: =IF(W3="Продажа",X3*Y3,-X3*Y3) -> 218514
A4: 0.39887731 | B4: NGH1 | C4: Купля | D4: 2.506 | E4: 1 | F4: =IF(C4="Продажа",D4*E4,-D4*E4) -> -2.506 | I4: 0.39887731 | J4: NGH1 | K4: Купля | L4: 2.506 | M4: 1 | N4: =IF(K4="Продажа",M4*L4,-M4*L4) -> -2.506 | T4: 3 | U4: 0.84600694 | V4: SiM1 | W4: Купля | X4: 73565 | Y4: 1 | Z4: U7A0067 | AA4: =IF(W4="Продажа",X4*Y4,-X4*Y4) -> -73565
A5: 0.39887731 | B5: NGH1 | C5: Купля | D5: 2.506 | E5: 1 | F5: =IF(C5="Продажа",D5*E5,-D5*E5) -> -2.506 | I5: 0.39887731 | J5: NGH1 | K5: Купля | L5: 2.506 | M5: 1 | N5: =IF(K5="Продажа",M5*L5,-M5*L5) -> -2.506 | T5: 4 | U5: 0.84600694 | V5: SiH1 | W5: Продажа | X5: 72793 | Y5: 1 | Z5: U7A0067 | AA5: =IF(W5="Продажа",X5*Y5,-X5*Y5) -> 72793
A6: 0.39887731 | B6: NGH1 | C6: Купля | D6: 2.506 | E6: 1 | F6: =IF(C6="Продажа",D6*E6,-D6*E6) -> -2.506 | I6: 0.39887731 | J6: NGH1 | K6: Купля | L6: 2.506 | M6: 1 | N6: =IF(K6="Продажа",M6*L6,-M6*L6) -> -2.506 | T6: 5 | U6: 0.84361111 | V6: SiM1 | W6: Купля | X6: 73587 | Y6: 1 | Z6: U7A0067 | AA6: =IF(W6="Продажа",X6*Y6,-X6*Y6) -> -73587
A7: 0.39701389 | B7: NGH1 | C7: Купля | D7: 2.505 | E7: 5 | F7: =IF(C7="Продажа",D7*E7,-D7*E7) -> -12.525 | I7: 0.39701389 | J7: NGH1 | K7: Купля | L7: 2.505 | M7: 5 | N7: =IF(K7="Продажа",M7*L7,-M7*L7) -> -12.525 | T7: 6 | U7: 0.84361111 | V7: SiM1 | W7: Купля | X7: 73587 | Y7: 1 | Z7: U7A0067 | AA7: =IF(W7="Продажа",X7*Y7,-X7*Y7) -> -73587
A8: 0.39701389 | B8: NGH1 | C8: Купля | D8: 2.505 | E8: 3 | F8: =IF(C8="Продажа",D8*E8,-D8*E8) -> -7.515 | I8: 0.39701389 | J8: NGH1 | K8: Купля | L8: 2.505 | M8: 3 | N8: =IF(K8="Продажа",M8*L8,-M8*L8) -> -7.515 | T8: 7 | U8: 0.84361111 | V8: SiM1 | W8: Купля | X8: 73587 | Y8: 1 | Z8: U7A0067 | AA8: =IF(W8="Продажа",X8*Y8,-X8*Y8) -> -73587
A9: 0.39701389 | B9: NGH1 | C9: Купля | D9: 2.505 | E9: 2 | F9: =IF(C9="Продажа",D9*E9,-D9*E9) -> -5.01 | I9: 0.39701389 | J9: NGH1 | K9: Купля | L9: 2.505 | M9: 2 | N9: =IF(K9="Продажа",M9*L9,-M9*L9) -> -5.01 | T9: 8 | U9: 0.84361111 | V9: SiH1 | W9: Продажа | X9: 72810 | Y9: 3 | Z9: U7A0067 | AA9: =IF(W9="Продажа",X9*Y9,-X9*Y9) -> 218430
A10: 0.39701389 | B10: NGH1 | C10: Купля | D10: 2.503 | E10: 1 | F10: =IF(C10="Продажа",D10*E10,-D10*E10) -> -2.503 | I10: 0.39701389 | J10: NGH1 | K10: Купля | L10: 2.503 | M10: 1 | N10: =IF(K10="Продажа",M10*L10,-M10*L10) -> -2.503 | T10: 9 | U10: 0.84359954 | V10: SiM1 | W10: Купля | X10: 73582 | Y10: 3 | Z10: U7A0067 | AA10: =IF(W10="Продажа",X10*Y10,-X10*Y10) -> -220746
A11: 0.39701389 | B11: NGH1 | C11: Купля | D11: 2.502 | E11: 1 | F11: =IF(C11="Продажа",D11*E11,-D11*E11) -> -2.502 | I11: 0.39701389 | J11: NGH1 | K11: Купля | L11: 2.502 | M11: 1 | N11: =IF(K11="Продажа",M11*L11,-M11*L11) -> -2.502 | T11: 10 | U11: 0.84359954 | V11: SiH1 | W11: Продажа | X11: 72806 | Y11: 3 | Z11: U7A0067 | AA11: =IF(W11="Продажа",X11*Y11,-X11*Y11) -> 218418
A12: 0.39675926 | B12: NGH1 | C12: Купля | D12: 2.504 | E12: 10 | F12: =IF(C12="Продажа",D12*E12,-D12*E12) -> -25.04 | I12: 0.39675926 | J12: NGH1 | K12: Купля | L12: 2.504 | M12: 10 | N12: =IF(K12="Продажа",M12*L12,-M12*L12) -> -25.04 | T12: 11 | U12: 0.84356481 | V12: SiM1 | W12: Купля | X12: 73578 | Y12: 1 | Z12: U7A0067 | AA12: =IF(W12="Продажа",X12*Y12,-X12*Y12) -> -73578
A13: 0.39675926 | B13: NGH1 | C13: Купля | D13: 2.504 | E13: 1 | F13: =IF(C13="Продажа",D13*E13,-D13*E13) -> -2.504 | I13: 0.39675926 | J13: NGH1 | K13: Купля | L13: 2.504 | M13: 1 | N13: =IF(K13="Продажа",M13*L13,-M13*L13) -> -2.504 | T13: 12 | U13: 0.84356481 | V13: SiM1 | W13: Купля | X13: 73578 | Y13: 2 | Z13: U7A0067 | AA13: =IF(W13="Продажа",X13*Y13,-X13*Y13) -> -147156
... A74: 0.36732639 | B74: SiM1 | C74: Купля | D74: 73660 | E74: 12 | F74: =IF(C74="Продажа",D74*E74,-D74*E74) -> -883920 | I74: 0.29724537 | J74: NGH1 | K74: Купля | L74: 2.483 | M74: 59 | N74: =IF(K74="Продажа",M74*L74,-M74*L74) -> -146.497 | T74: 73 | U74: 0.84065972 | V74: SiH1 | W74: Продажа | X74: 72762 | Y74: 1 | Z74: U7A0067 | AA74: =IF(W74="Продажа",X74*Y74,-X74*Y74) -> 72762
A75: 0.36732639 | B75: SiM1 | C75: Купля | D75: 73660 | E75: 1 | F75: =IF(C75="Продажа",D75*E75,-D75*E75) -> -73660 | N75: =SUM(N2:N74) -> 249.464 | T75: 74 | U75: 0.84065972 | V75: SiM1 | W75: Купля | X75: 73535 | Y75: 2 | Z75: U7A0067 | AA75: =IF(W75="Продажа",X75*Y75,-X75*Y75) -> -147070
A76: 0.36732639 | B76: SiM1 | C76: Купля | D76: 73660 | E76: 4 | F76: =IF(C76="Продажа",D76*E76,-D76*E76) -> -294640 | T76: 75 | U76: 0.84065972 | V76: SiH1 | W76: Продажа | X76: 72762 | Y76: 2 | Z76: U7A0067 | AA76: =IF(W76="Продажа",X76*Y76,-X76*Y76) -> 145524
A77: 0.36732639 | B77: SiM1 | C77: Купля | D77: 73660 | E77: 1 | F77: =IF(C77="Продажа",D77*E77,-D77*E77) -> -73660 | T77: 76 | U77: 0.84065972 | V77: SiM1 | W77: Купля | X77: 73535 | Y77: 3 | Z77: U7A0067 | AA77: =IF(W77="Продажа",X77*Y77,-X77*Y77) -> -220605
A78: 0.36732639 | B78: SiM1 | C78: Купля | D78: 73660 | E78: 4 | F78: =IF(C78="Продажа",D78*E78,-D78*E78) -> -294640 | T78: 77 | U78: 0.84065972 | V78: SiH1 | W78: Продажа | X78: 72762 | Y78: 3 | Z78: U7A0067 | AA78: =IF(W78="Продажа",X78*Y78,-X78*Y78) -> 218286
A79: 0.36732639 | B79: SiM1 | C79: Купля | D79: 73660 | E79: 2 | F79: =IF(C79="Продажа",D79*E79,-D79*E79) -> -147320 | T79: 78 | U79: 0.84065972 | V79: SiM1 | W79: Купля | X79: 73535 | Y79: 3 | Z79: U7A0067 | AA79: =IF(W79="Продажа",X79*Y79,-X79*Y79) -> -220605
A80: 0.36732639 | B80: SiM1 | C80: Купля | D80: 73660 | E80: 2 | F80: =IF(C80="Продажа",D80*E80,-D80*E80) -> -147320 | T80: 79 | U80: 0.84065972 | V80: SiH1 | W80: Продажа | X80: 72762 | Y80: 3 | Z80: U7A0067 | AA80: =IF(W80="Продажа",X80*Y80,-X80*Y80) -> 218286
A81: 0.36728009 | B81: SiH1 | C81: Продажа | D81: 72886 | E81: 50 | F81: =IF(C81="Продажа",D81*E81,-D81*E81) -> 3644300 | T81: 80 | U81: 0.84065972 | V81: SiM1 | W81: Купля | X81: 73535 | Y81: 2 | Z81: U7A0067 | AA81: =IF(W81="Продажа",X81*Y81,-X81*Y81) -> -147070
A82: 0.36587963 | B82: NGH1 | C82: Купля | D82: 2.495 | E82: 10 | F82: =IF(C82="Продажа",D82*E82,-D82*E82) -> -24.95 | T82: 81 | U82: 0.84065972 | V82: SiH1 | W82: Продажа | X82: 72762 | Y82: 2 | Z82: U7A0067 | AA82: =IF(W82="Продажа",X82*Y82,-X82*Y82) -> 145524
A83: 0.36085648 | B83: SiM1 | C83: Купля | D83: 73648 | E83: 8 | F83: =IF(C83="Продажа",D83*E83,-D83*E83) -> -589184 | T83: 82 | U83: 0.84064815 | V83: SiM1 | W83: Купля | X83: 73535 | Y83: 1 | Z83: U7A0067 | AA83: =IF(W83="Продажа",X83*Y83,-X83*Y83) -> -73535
A84: 0.36079861 | B84: SiM1 | C84: Купля | D84: 73648 | E84: 2 | F84: =IF(C84="Продажа",D84*E84,-D84*E84) -> -147296 | T84: 83 | U84: 0.84064815 | V84: SiH1 | W84: Продажа | X84: 72762 | Y84: 1 | Z84: U7A0067 | AA84: =IF(W84="Продажа",X84*Y84,-X84*Y84) -> 72762
A85: 0.36078704 | B85: SiM1 | C85: Купля | D85: 73648 | E85: 1 | F85: =IF(C85="Продажа",D85*E85,-D85*E85) -> -73648 | T85: 84 | U85: 0.84064815 | V85: SiM1 | W85: Купля | X85: 73535 | Y85: 3 | Z85: U7A0067 | AA85: =IF(W85="Продажа",X85*Y85,-X85*Y85) -> -220605
A86: 0.36077546 | B86: SiM1 | C86: Купля | D86: 73648 | E86: 1 | F86: =IF(C86="Продажа",D86*E86,-D86*E86) -> -73648 | T86: 85 | U86: 0.84064815 | V86: SiH1 | W86: Продажа | X86: 72762 | Y86: 3 | Z86: U7A0067 | AA86: =IF(W86="Продажа",X86*Y86,-X86*Y86) -> 218286
A87: 0.36077546 | B87: SiM1 | C87: Купля | D87: 73648 | E87: 2 | F87: =IF(C87="Продажа",D87*E87,-D87*E87) -> -147296 | T87: 86 | U87: 0.84064815 | V87: SiM1 | W87: Купля | X87: 73535 | Y87: 3 | Z87: U7A0067 | AA87: =IF(W87="Продажа",X87*Y87,-X87*Y87) -> -220605
... A177: 0.29724537 | B177: NGH1 | C177: Купля | D177: 2.483 | E177: 59 | F177: =IF(C177="Продажа",D177*E177,-D177*E177) -> -146.497 | T177: 176 | U177: 0.82297454 | V177: SiH1 | W177: Продажа | X177: 72801 | Y177: 3 | Z177: U7A0067 | AA177: =IF(W177="Продажа",X177*Y177,-X177*Y177) -> 218403
F178: =SUM(F31:F177) -> 3375634.7 | T178: 177 | U178: 0.82295139 | V178: SiM1 | W178: Купля | X178: 73576 | Y178: 3 | Z178: U7A0067 | AA178: =IF(W178="Продажа",X178*Y178,-X178*Y178) -> -220728
T179: 178 | U179: 0.82295139 | V179: SiH1 | W179: Продажа | X179: 72801 | Y179: 3 | Z179: U7A0067 | AA179: =IF(W179="Продажа",X179*Y179,-X179*Y179) -> 218403
T180: 179 | U180: 0.82289352 | V180: SiM1 | W180: Купля | X180: 73575 | Y180: 3 | Z180: U7A0067 | AA180: =IF(W180="Продажа",X180*Y180,-X180*Y180) -> -220725
T181: 180 | U181: 0.82289352 | V181: SiH1 | W181: Продажа | X181: 72800 | Y181: 3 | Z181: U7A0067 | AA181: =IF(W181="Продажа",X181*Y181,-X181*Y181) -> 218400
T182: 181 | U182: 0.8227662 | V182: SiM1 | W182: Купля | X182: 73576 | Y182: 3 | Z182: U7A0067 | AA182: =IF(W182="Продажа",X182*Y182,-X182*Y182) -> -220728
T183: 182 | U183: 0.8227662 | V183: SiH1 | W183: Продажа | X183: 72799 | Y183: 3 | Z183: U7A0067 | AA183: =IF(W183="Продажа",X183*Y183,-X183*Y183) -> 218397
T184: 183 | U184: 0.82273148 | V184: SiM1 | W184: Купля | X184: 73575 | Y184: 1 | Z184: U7A0067 | AA184: =IF(W184="Продажа",X184*Y184,-X184*Y184) -> -73575
T185: 184 | U185: 0.82273148 | V185: SiM1 | W185: Купля | X185: 73573 | Y185: 2 | Z185: U7A0067 | AA185: =IF(W185="Продажа",X185*Y185,-X185*Y185) -> -147146
T186: 185 | U186: 0.82273148 | V186: SiH1 | W186: Продажа | X186: 72798 | Y186: 3 | Z186: U7A0067 | AA186: =IF(W186="Продажа",X186*Y186,-X186*Y186) -> 218394
T187: 186 | U187: 0.82273148 | V187: SiM1 | W187: Купля | X187: 73573 | Y187: 3 | Z187: U7A0067 | AA187: =IF(W187="Продажа",X187*Y187,-X187*Y187) -> -220719
T188: 187 | U188: 0.82273148 | V188: SiH1 | W188: Продажа | X188: 72798 | Y188: 3 | Z188: U7A0067 | AA188: =IF(W188="Продажа",X188*Y188,-X188*Y188) -> 218394
T189: 188 | U189: 0.82268519 | V189: SiM1 | W189: Купля | X189: 73573 | Y189: 1 | Z189: U7A0067 | AA189: =IF(W189="Продажа",X189*Y189,-X189*Y189) -> -73573
...

Sheet 17.03.21
A1: Время | B1: Инструмент сокр. | C1: Операция | D1: Цена | E1: Кол-во | F1: Фин рез | H1: Время | I1: Инструмент сокр. | J1: Операция | K1: Цена | L1: Кол-во | M1: Фин рез
A2: 0.85674769 | B2: SiM1 | C2: Купля | D2: 73616 | E2: 3 | F2: =IF(C2="Продажа",D2*E2,-D2*E2) -> -220848 | H2: 0.41524306 | I2: NGH1 | J2: Купля | K2: 2.543 | L2: 8 | M2: =IF(J2="Продажа",K2*L2,-K2*L2) -> -20.344
A3: 0.85674769 | B3: SiH1 | C3: Продажа | D3: 72838 | E3: 3 | F3: =IF(C3="Продажа",D3*E3,-D3*E3) -> 218514 | H3: 0.41309028 | I3: NGH1 | J3: Купля | K3: 2.54 | L3: 5 | M3: =IF(J3="Продажа",K3*L3,-K3*L3) -> -12.7
A4: 0.84600694 | B4: SiM1 | C4: Купля | D4: 73565 | E4: 1 | F4: =IF(C4="Продажа",D4*E4,-D4*E4) -> -73565 | H4: 0.40344907 | I4: NGH1 | J4: Продажа | K4: 2.537 | L4: 13 | M4: =IF(J4="Продажа",K4*L4,-K4*L4) -> 32.981
A5: 0.84600694 | B5: SiH1 | C5: Продажа | D5: 72793 | E5: 1 | F5: =IF(C5="Продажа",D5*E5,-D5*E5) -> 72793 | H5: 0.39958333 | I5: NGH1 | J5: Продажа | K5: 2.53 | L5: 1 | M5: =IF(J5="Продажа",K5*L5,-K5*L5) -> 2.53
A6: 0.84361111 | B6: SiM1 | C6: Купля | D6: 73587 | E6: 1 | F6: =IF(C6="Продажа",D6*E6,-D6*E6) -> -73587 | H6: 0.39958333 | I6: NGH1 | J6: Продажа | K6: 2.53 | L6: 1 | M6: =IF(J6="Продажа",K6*L6,-K6*L6) -> 2.53
A7: 0.84361111 | B7: SiM1 | C7: Купля | D7: 73587 | E7: 1 | F7: =IF(C7="Продажа",D7*E7,-D7*E7) -> -73587 | H7: 0.39958333 | I7: NGH1 | J7: Продажа | K7: 2.53 | L7: 1 | M7: =IF(J7="Продажа",K7*L7,-K7*L7) -> 2.53
A8: 0.84361111 | B8: SiM1 | C8: Купля | D8: 73587 | E8: 1 | F8: =IF(C8="Продажа",D8*E8,-D8*E8) -> -73587 | H8: 0.39958333 | I8: NGH1 | J8: Продажа | K8: 2.53 | L8: 6 | M8: =IF(J8="Продажа",K8*L8,-K8*L8) -> 15.18
A9: 0.84361111 | B9: SiH1 | C9: Продажа | D9: 72810 | E9: 3 | F9: =IF(C9="Продажа",D9*E9,-D9*E9) -> 218430 | H9: 0.39958333 | I9: NGH1 | J9: Продажа | K9: 2.53 | L9: 1 | M9: =IF(J9="Продажа",K9*L9,-K9*L9) -> 2.53
A10: 0.84359954 | B10: SiM1 | C10: Купля | D10: 73582 | E10: 3 | F10: =IF(C10="Продажа",D10*E10,-D10*E10) -> -220746 | H10: 0.39958333 | I10: NGH1 | J10: Продажа | K10: 2.53 | L10: 1 | M10: =IF(J10="Продажа",K10*L10,-K10*L10) -> 2.53
A11: 0.84359954 | B11: SiH1 | C11: Продажа | D11: 72806 | E11: 3 | F11: =IF(C11="Продажа",D11*E11,-D11*E11) -> 218418 | H11: 0.39958333 | I11: NGH1 | J11: Продажа | K11: 2.531 | L11: 1 | M11: =IF(J11="Продажа",K11*L11,-K11*L11) -> 2.531
A12: 0.84356481 | B12: SiM1 | C12: Купля | D12: 73578 | E12: 1 | F12: =IF(C12="Продажа",D12*E12,-D12*E12) -> -73578 | H12: 0.39958333 | I12: NGH1 | J12: Продажа | K12: 2.531 | L12: 1 | M12: =IF(J12="Продажа",K12*L12,-K12*L12) -> 2.531
A13: 0.84356481 | B13: SiM1 | C13: Купля | D13: 73578 | E13: 2 | F13: =IF(C13="Продажа",D13*E13,-D13*E13) -> -147156 | H13: 0.39958333 | I13: NGH1 | J13: Продажа | K13: 2.531 | L13: 1 | M13: =IF(J13="Продажа",K13*L13,-K13*L13) -> 2.531
... A90: 0.82445602 | B90: SiH1 | C90: Продажа | D90: 72810 | E90: 3 | F90: =IF(C90="Продажа",D90*E90,-D90*E90) -> 218430 | H90: 0.29614583 | I90: GDH1 | J90: Продажа | K90: 1735.3 | L90: 154 | M90: =IF(J90="Продажа",K90*L90,-K90*L90) -> 267236.2
A91: 0.82438657 | B91: SiM1 | C91: Купля | D91: 73581 | E91: 3 | F91: =IF(C91="Продажа",D91*E91,-D91*E91) -> -220743 | M91: =SUM(M2:M90) -> 193783.28
A92: 0.82438657 | B92: SiH1 | C92: Продажа | D92: 72806 | E92: 3 | F92: =IF(C92="Продажа",D92*E92,-D92*E92) -> 218418
A93: 0.82438657 | B93: SiM1 | C93: Купля | D93: 73581 | E93: 3 | F93: =IF(C93="Продажа",D93*E93,-D93*E93) -> -220743
A94: 0.82438657 | B94: SiH1 | C94: Продажа | D94: 72806 | E94: 3 | F94: =IF(C94="Продажа",D94*E94,-D94*E94) -> 218418
A95: 0.824375 | B95: SiM1 | C95: Купля | D95: 73581 | E95: 3 | F95: =IF(C95="Продажа",D95*E95,-D95*E95) -> -220743
A96: 0.824375 | B96: SiH1 | C96: Продажа | D96: 72806 | E96: 3 | F96: =IF(C96="Продажа",D96*E96,-D96*E96) -> 218418
A97: 0.824375 | B97: SiM1 | C97: Купля | D97: 73581 | E97: 3 | F97: =IF(C97="Продажа",D97*E97,-D97*E97) -> -220743
A98: 0.824375 | B98: SiH1 | C98: Продажа | D98: 72806 | E98: 3 | F98: =IF(C98="Продажа",D98*E98,-D98*E98) -> 218418
A99: 0.824375 | B99: SiM1 | C99: Купля | D99: 73581 | E99: 3 | F99: =IF(C99="Продажа",D99*E99,-D99*E99) -> -220743
A100: 0.824375 | B100: SiH1 | C100: Продажа | D100: 72806 | E100: 3 | F100: =IF(C100="Продажа",D100*E100,-D100*E100) -> 218418
A101: 0.824375 | B101: SiM1 | C101: Купля | D101: 73581 | E101: 3 | F101: =IF(C101="Продажа",D101*E101,-D101*E101) -> -220743
A102: 0.824375 | B102: SiH1 | C102: Продажа | D102: 72806 | E102: 3 | F102: =IF(C102="Продажа",D102*E102,-D102*E102) -> 218418
A103: 0.824375 | B103: SiM1 | C103: Купля | D103: 73581 | E103: 3 | F103: =IF(C103="Продажа",D103*E103,-D103*E103) -> -220743
... A365: 0.29614583 | B365: GDH1 | C365: Продажа | D365: 1735.3 | E365: 154 | F365: =IF(C365="Продажа",D365*E365,-D365*E365) -> 267236.2
F366: =SUM(F2:F365) -> -53539.717

Sheet 18.03.21
A1: Время | B1: Инструмент сокр. | C1: Операция | D1: Цена | E1: Кол-во | F1: Фин рез | G1: Дата сделки | I1: Время | J1: Инструмент сокр. | K1: Операция | L1: Цена | M1: Кол-во | N1: Фин рез | O1: Дата сделки
A2: 0.35027778 | B2: SiM1 | C2: Купля | D2: 74531 | E2: 1 | F2: =IF(C2="Продажа",D2*E2,-D2*E2) -> -74531 | G2: 44273 | I2: 0.33625 | J2: SVH1 | K2: Продажа | L2: 26.47 | M2: 376 | N2: =IF(K2="Продажа",L2*M2,-L2*M2) -> 9952.72 | O2: 44273
A3: 0.35027778 | B3: SiM1 | C3: Купля | D3: 74531 | E3: 1 | F3: =IF(C3="Продажа",D3*E3,-D3*E3) -> -74531 | G3: 44273 | I3: 0.33625 | J3: SVH1 | K3: Продажа | L3: 26.47 | M3: 399 | N3: =IF(K3="Продажа",L3*M3,-L3*M3) -> 10561.53 | O3: 44273
A4: 0.35027778 | B4: SiH1 | C4: Продажа | D4: 73736 | E4: 2 | F4: =IF(C4="Продажа",D4*E4,-D4*E4) -> 147472 | G4: 44273 | I4: 0.33623843 | J4: SVH1 | K4: Продажа | L4: 26.48 | M4: 225 | N4: =IF(K4="Продажа",L4*M4,-L4*M4) -> 5958 | O4: 44273
A5: 0.34988426 | B5: SiM1 | C5: Купля | D5: 74536 | E5: 1 | F5: =IF(C5="Продажа",D5*E5,-D5*E5) -> -74536 | G5: 44273 | I5: 0.33572917 | J5: SVH1 | K5: Купля | L5: 26.5 | M5: 3 | N5: =IF(K5="Продажа",L5*M5,-L5*M5) -> -79.5 | O5: 44273
A6: 0.34988426 | B6: SiH1 | C6: Продажа | D6: 73741 | E6: 1 | F6: =IF(C6="Продажа",D6*E6,-D6*E6) -> 73741 | G6: 44273 | I6: 0.33572917 | J6: SVH1 | K6: Купля | L6: 26.5 | M6: 50 | N6: =IF(K6="Продажа",L6*M6,-L6*M6) -> -1325 | O6: 44273
A7: 0.34980324 | B7: SiM1 | C7: Купля | D7: 74536 | E7: 3 | F7: =IF(C7="Продажа",D7*E7,-D7*E7) -> -223608 | G7: 44273 | I7: 0.33572917 | J7: SVH1 | K7: Купля | L7: 26.5 | M7: 1 | N7: =IF(K7="Продажа",L7*M7,-L7*M7) -> -26.5 | O7: 44273
A8: 0.34980324 | B8: SiH1 | C8: Продажа | D8: 73741 | E8: 3 | F8: =IF(C8="Продажа",D8*E8,-D8*E8) -> 221223 | G8: 44273 | I8: 0.33572917 | J8: SVH1 | K8: Купля | L8: 26.5 | M8: 4 | N8: =IF(K8="Продажа",L8*M8,-L8*M8) -> -106 | O8: 44273
A9: 0.34946759 | B9: SiM1 | C9: Купля | D9: 74540 | E9: 1 | F9: =IF(C9="Продажа",D9*E9,-D9*E9) -> -74540 | G9: 44273 | I9: 0.33342593 | J9: SVH1 | K9: Купля | L9: 26.44 | M9: 942 | N9: =IF(K9="Продажа",L9*M9,-L9*M9) -> -24906.48 | O9: 44273
A10: 0.34946759 | B10: SiH1 | C10: Продажа | D10: 73741 | E10: 1 | F10: =IF(C10="Продажа",D10*E10,-D10*E10) -> 73741 | G10: 44273 | N10: =SUM(N2:N9) -> 28.77
A11: 0.34945602 | B11: SiM1 | C11: Купля | D11: 74541 | E11: 1 | F11: =IF(C11="Продажа",D11*E11,-D11*E11) -> -74541 | G11: 44273
A12: 0.34945602 | B12: SiM1 | C12: Купля | D12: 74541 | E12: 1 | F12: =IF(C12="Продажа",D12*E12,-D12*E12) -> -74541 | G12: 44273
A13: 0.34945602 | B13: SiM1 | C13: Купля | D13: 74541 | E13: 1 | F13: =IF(C13="Продажа",D13*E13,-D13*E13) -> -74541 | G13: 44273
A14: 0.34945602 | B14: SiH1 | C14: Продажа | D14: 73746 | E14: 3 | F14: =IF(C14="Продажа",D14*E14,-D14*E14) -> 221238 | G14: 44273
A15: 0.34924769 | B15: SiM1 | C15: Купля | D15: 74547 | E15: 1 | F15: =IF(C15="Продажа",D15*E15,-D15*E15) -> -74547 | G15: 44273
A16: 0.34924769 | B16: SiM1 | C16: Купля | D16: 74547 | E16: 1 | F16: =IF(C16="Продажа",D16*E16,-D16*E16) -> -74547 | G16: 44273
A17: 0.34924769 | B17: SiM1 | C17: Купля | D17: 74547 | E17: 1 | F17: =IF(C17="Продажа",D17*E17,-D17*E17) -> -74547 | G17: 44273
A18: 0.34924769 | B18: SiH1 | C18: Продажа | D18: 73750 | E18: 3 | F18: =IF(C18="Продажа",D18*E18,-D18*E18) -> 221250 | G18: 44273
A19: 0.34924769 | B19: SiM1 | C19: Купля | D19: 74548 | E19: 1 | F19: =IF(C19="Продажа",D19*E19,-D19*E19) -> -74548 | G19: 44273
A20: 0.34924769 | B20: SiH1 | C20: Продажа | D20: 73753 | E20: 1 | F20: =IF(C20="Продажа",D20*E20,-D20*E20) -> 73753 | G20: 44273
A21: 0.34899306 | B21: SiM1 | C21: Купля | D21: 74553 | E21: 1 | F21: =IF(C21="Продажа",D21*E21,-D21*E21) -> -74553 | G21: 44273
A22: 0.34899306 | B22: SiH1 | C22: Продажа | D22: 73758 | E22: 1 | F22: =IF(C22="Продажа",D22*E22,-D22*E22) -> 73758 | G22: 44273
... A430: 0.875 | B430: GDH1 | C430: Купля | D430: 1732.8 | E430: 98 | F430: =IF(C430="Продажа",D430*E430,-D430*E430) -> -169814.4 | G430: 44272
F431: =SUM(F2:F430) -> -397098.03

Sheet 19.03.21
A1: Время | B1: Инструмент сокр. | C1: Операция | D1: Цена | E1: Кол-во | F1: Счет | G1: Дата сделки | H1: Фин рез
A2: 0.36509259 | B2: NGH1 | C2: Продажа | D2: 2.49 | E2: 3 | F2: U7A0067 | G2: 44274 | H2: =IF(C2="Продажа",D2*E2,-D2*E2) -> 7.47
A3: 0.36447917 | B3: NGH1 | C3: Продажа | D3: 2.489 | E3: 4 | F3: U7A0067 | G3: 44274 | H3: =IF(C3="Продажа",D3*E3,-D3*E3) -> 9.956
A4: 0.36164352 | B4: NGH1 | C4: Продажа | D4: 2.49 | E4: 3 | F4: U7A0067 | G4: 44274 | H4: =IF(C4="Продажа",D4*E4,-D4*E4) -> 7.47
A5: 0.36164352 | B5: NGH1 | C5: Продажа | D5: 2.489 | E5: 3 | F5: U7A0067 | G5: 44274 | H5: =IF(C5="Продажа",D5*E5,-D5*E5) -> 7.467
A6: 0.35961806 | B6: NGH1 | C6: Продажа | D6: 2.489 | E6: 4 | F6: U7A0067 | G6: 44274 | H6: =IF(C6="Продажа",D6*E6,-D6*E6) -> 9.956
A7: 0.33788194 | B7: NGH1 | C7: Продажа | D7: 2.489 | E7: 2 | F7: U7A0067 | G7: 44274 | H7: =IF(C7="Продажа",D7*E7,-D7*E7) -> 4.978
A8: 0.33679398 | B8: NGH1 | C8: Продажа | D8: 2.489 | E8: 1 | F8: U7A0067 | G8: 44274 | H8: =IF(C8="Продажа",D8*E8,-D8*E8) -> 2.489
A9: 0.32967593 | B9: BRK1 | C9: Продажа | D9: 63.38 | E9: 25 | F9: U7A0067 | G9: 44274 | H9: =IF(C9="Продажа",D9*E9,-D9*E9) -> 1584.5
A10: 0.32967593 | B10: BRK1 | C10: Продажа | D10: 63.37 | E10: 25 | F10: U7A0067 | G10: 44274 | H10: =IF(C10="Продажа",D10*E10,-D10*E10) -> 1584.25
A11: 0.32967593 | B11: BRJ1 | C11: Продажа | D11: 63.5 | E11: 40 | F11: U7A0067 | G11: 44274 | H11: =IF(C11="Продажа",D11*E11,-D11*E11) -> 2540
A12: 0.32917824 | B12: NGH1 | C12: Продажа | D12: 2.493 | E12: 1 | F12: U7A0067 | G12: 44274 | H12: =IF(C12="Продажа",D12*E12,-D12*E12) -> 2.493
A13: 0.32908565 | B13: NGH1 | C13: Продажа | D13: 2.493 | E13: 1 | F13: U7A0067 | G13: 44274 | H13: =IF(C13="Продажа",D13*E13,-D13*E13) -> 2.493
... A71: 0.29665509 | B71: NGH1 | C71: Продажа | D71: 2.484 | E71: 22 | F71: U7A0067 | G71: 44274 | H71: =IF(C71="Продажа",D71*E71,-D71*E71) -> 54.648
H72: =SUM(H2:H71) -> -18741.954
